{"uuid": "4d939000-61ba-4225-848b-27a06dda5668", "children": ["38aee4a5-18ee-482d-86ac-d9be6ff993b9", "33d156d8-ea4e-4fe2-b6f0-935138e7b4d2"], "befores": [{"name": "setup", "status": "broken", "statusDetails": {"message": "selenium.common.exceptions.WebDriverException: Message: An unknown server-side error occurred while processing the command. Original error: Could not find a connected Android device in 20342ms.\nStacktrace:\nUnknownError: An unknown server-side error occurred while processing the command. Original error: Could not find a connected Android device in 20342ms.\n    at getResponseForW3CError (C:\\Program Files\\Appium Server GUI\\resources\\app\\node_modules\\appium\\node_modules\\appium-base-driver\\lib\\protocol\\errors.js:804:9)\n    at asyncHandler (C:\\Program Files\\Appium Server GUI\\resources\\app\\node_modules\\appium\\node_modules\\appium-base-driver\\lib\\protocol\\protocol.js:380:37)\n", "trace": "  File \"C:\\Users\\ELCOT\\PycharmProjects\\TE Lock\\venv\\lib\\site-packages\\pluggy\\_callers.py\", line 39, in _multicall\n    res = hook_impl.function(*args)\n  File \"C:\\Users\\ELCOT\\PycharmProjects\\TE Lock\\venv\\lib\\site-packages\\_pytest\\fixtures.py\", line 1111, in pytest_fixture_setup\n    result = call_fixture_func(fixturefunc, request, kwargs)\n  File \"C:\\Users\\ELCOT\\PycharmProjects\\TE Lock\\venv\\lib\\site-packages\\_pytest\\fixtures.py\", line 883, in call_fixture_func\n    fixture_result = next(generator)\n  File \"C:\\Users\\ELCOT\\PycharmProjects\\TE Lock\\Main file\\conftest.py\", line 24, in setup\n    driver = webdriver.Remote(\"http://localhost:4723/wd/hub\", desired_cap)\n  File \"C:\\Users\\ELCOT\\PycharmProjects\\TE Lock\\venv\\lib\\site-packages\\appium\\webdriver\\webdriver.py\", line 274, in __init__\n    super().__init__(\n  File \"C:\\Users\\ELCOT\\PycharmProjects\\TE Lock\\venv\\lib\\site-packages\\selenium\\webdriver\\remote\\webdriver.py\", line 275, in __init__\n    self.start_session(capabilities, browser_profile)\n  File \"C:\\Users\\ELCOT\\PycharmProjects\\TE Lock\\venv\\lib\\site-packages\\appium\\webdriver\\webdriver.py\", line 369, in start_session\n    response = self.execute(RemoteCommand.NEW_SESSION, parameters)\n  File \"C:\\Users\\ELCOT\\PycharmProjects\\TE Lock\\venv\\lib\\site-packages\\selenium\\webdriver\\remote\\webdriver.py\", line 430, in execute\n    self.error_handler.check_response(response)\n  File \"C:\\Users\\ELCOT\\PycharmProjects\\TE Lock\\venv\\lib\\site-packages\\selenium\\webdriver\\remote\\errorhandler.py\", line 247, in check_response\n    raise exception_class(message, screen, stacktrace)\n"}, "start": 1654004476427, "stop": 1654004520679}], "start": 1654004476427, "stop": 1654004523632}